Sourcing python-remove-tests-dir-hook
Sourcing python-catch-conflicts-hook.sh
Sourcing python-remove-bin-bytecode-hook.sh
Sourcing pypa-install-hook
Using pypaInstallPhase
Sourcing python-imports-check-hook.sh
Using pythonImportsCheckPhase
Sourcing python-namespaces-hook
Sourcing pip-build-hook
Using pipBuildPhase
Using pipShellHook
@nix { "action": "setPhase", "phase": "unpackPhase" }
Running phase: unpackPhase
unpacking source archive /nix/store/bvcngabq8j95wvibf2h30lwhyibb1ykn-pyquaternion-0.9.9.tar.gz
source root is pyquaternion-0.9.9
setting SOURCE_DATE_EPOCH to timestamp 1601861488 of file pyquaternion-0.9.9/setup.cfg
@nix { "action": "setPhase", "phase": "patchPhase" }
Running phase: patchPhase
@nix { "action": "setPhase", "phase": "updateAutotoolsGnuConfigScriptsPhase" }
Running phase: updateAutotoolsGnuConfigScriptsPhase
@nix { "action": "setPhase", "phase": "configurePhase" }
Running phase: configurePhase
no configure script, doing nothing
@nix { "action": "setPhase", "phase": "buildPhase" }
Running phase: buildPhase
Executing pipBuildPhase
Creating a wheel...
[33mWARNING: The directory '/homeless-shelter/.cache/pip' or its parent directory is not owned or is not writable by the current user. The cache has been disabled. Check the permissions and owner of that directory. If executing pip with sudo, you should use sudo's -H flag.[0m[33m
[0mProcessing /build/pyquaternion-0.9.9
  Running command python setup.py egg_info
  Traceback (most recent call last):
    File "<string>", line 2, in <module>
    File "<pip-setuptools-caller>", line 34, in <module>
    File "/build/pyquaternion-0.9.9/setup.py", line 14, in <module>
      with open(os.path.join(here, 'VERSION.txt')) as version_file:
           ^^^^^^^^^^^^^^^^^^^^^^^^^^^^^^^^^^^^^^^
    File "<frozen codecs>", line 918, in open
  FileNotFoundError: [Errno 2] No such file or directory: '/build/pyquaternion-0.9.9/VERSION.txt'
  [1;31merror[0m: [1msubprocess-exited-with-error[0m
  
  [31mÃ—[0m [32mpython setup.py egg_info[0m did not run successfully.
  [31mâ”‚[0m exit code: [1;36m1[0m
  [31mâ•°â”€>[0m See above for output.
  
  [1;35mnote[0m: This error originates from a subprocess, and is likely not a problem with pip.
  [1;35mfull command[0m: [34m/nix/store/5k91mg4qjylxbfvrv748smfh51ppjq0g-python3-3.11.6/bin/python3.11 -c '[0m
[34m  exec(compile('"'"''"'"''"'"'[0m
[34m  # This is <pip-setuptools-caller> -- a caller that pip uses to run setup.py[0m
[34m  #[0m
[34m  # - It imports setuptools before invoking setup.py, to enable projects that directly[0m
[34m  #   import from `distutils.core` to work with newer packaging standards.[0m
[34m  # - It provides a clear error message when setuptools is not installed.[0m
[34m  # - It sets `sys.argv[0]` to the underlying `setup.py`, when invoking `setup.py` so[0m
[34m  #   setuptools doesn'"'"'t think the script is `-c`. This avoids the following warning:[0m
[34m  #     manifest_maker: standard file '"'"'-c'"'"' not found".[0m
[34m  # - It generates a shim setup.py, for handling setup.cfg-only projects.[0m
[34m  import os, sys, tokenize[0m
[34m  [0m
[34m  try:[0m
[34m      import setuptools[0m
[34m  except ImportError as error:[0m
[34m      print([0m
[34m          "ERROR: Can not execute `setup.py` since setuptools is not available in "[0m
[34m          "the build environment.",[0m
[34m          file=sys.stderr,[0m
[34m      )[0m
[34m      sys.exit(1)[0m
[34m  [0m
[34m  __file__ = %r[0m
[34m  sys.argv[0] = __file__[0m
[34m  [0m
[34m  if os.path.exists(__file__):[0m
[34m      filename = __file__[0m
[34m      with tokenize.open(__file__) as f:[0m
[34m          setup_py_code = f.read()[0m
[34m  else:[0m
[34m      filename = "<auto-generated setuptools caller>"[0m
[34m      setup_py_code = "from setuptools import setup; setup()"[0m
[34m  [0m
[34m  exec(compile(setup_py_code, filename, "exec"))[0m
[34m  '"'"''"'"''"'"' % ('"'"'/build/pyquaternion-0.9.9/setup.py'"'"',), "<pip-setuptools-caller>", "exec"))' egg_info --egg-base /build/pip-pip-egg-info-68ro5h7g[0m
  [1;35mcwd[0m: /build/pyquaternion-0.9.9/
  Preparing metadata (setup.py) ... [?25l[?25herror
[1;31merror[0m: [1mmetadata-generation-failed[0m

[31mÃ—[0m Encountered error while generating package metadata.
[31mâ•°â”€>[0m See above for output.

[1;35mnote[0m: This is an issue with the package mentioned above, not pip.
[1;36mhint[0m: See above for details.
